Workbook

Sheet Read me
A1: Capture register (SOCO-REC-DS-003a)
A3: What this is | B3: The single list of what the app, the backend and the recommendation service must capture, field by field. Updated 22 September 2026. The Wave 1A build list wins where the two differ. | H3: Aravinth | I3: For each of your rows, "What must be built" / "What the value must be" is the rule you have to code to. "How to check it is right" is how you will check your own work.
A4: What is in it | B4: 13 events, 65 fields and 9 data model changes, plus the Rules sheet that most rows point to. | H4: Allen | I4: Builds your rows (E1, served_items, the ingest route, ml_events) the same way, and reports status the same way.
A5: How to read a row | B5: Status says where it stood on 22 September 2026. For a built row, Built on / due by is the build date. For rows still to build it is blank: the step each row sits in is in the Wave 1A build list, which also names the item (APP, DB or ENG) that builds it. What must be built / What the value must be is the rule to build and test against. Decided in lists the related codes in this register. | I5: Run the code test. The test reads the register. Generate the schema file both sides build against from it.
A6: Built | B6: Reported built. Checked by the How to check column. | I6: Report failures in two kinds: names missing from the register, or the test not being able to read the layout.
A7: Verify | B7: Reported built, one check still to run. | H7: Aravinth | I7: Keeps the register in step with the build list: dates every change in the Note, and adds rows only for new fields in the API contract.
A8: To build | B8: Accepted, not built yet. The step is in the Wave 1A build list.
A9: Deferred | B9: After Wave 1A. The consequence is in the Note.
A10: Closed | B10: Nothing to build: already captured or not needed.
A11: Changing a row | B11: Change it here and date the change in the Note. Any change to an event, a field or a retention period is agreed in writing by Allen and Aravinth first.
A12: History | B12: Earlier versions are withdrawn. This is the only version.
A14: Where things stand
A15: Status | B15: Events | C15: Fields | D15: Data model changes
A16: Built | B16: =COUNTIF('1 Events'!F5:F17,"Built") -> 4 | C16: =COUNTIF('2 Fields'!H5:H69,"Built") -> 28 | D16: =COUNTIF('3 Data model changes'!E5:E13,"Built") -> 0
A17: Verify | B17: =COUNTIF('1 Events'!F5:F17,"Verify") -> 0 | C17: =COUNTIF('2 Fields'!H5:H69,"Verify") -> 1 | D17: =COUNTIF('3 Data model changes'!E5:E13,"Verify") -> 1
A18: To build | B18: =COUNTIF('1 Events'!F5:F17,"To build") -> 4 | C18: =COUNTIF('2 Fields'!H5:H69,"To build") -> 10 | D18: =COUNTIF('3 Data model changes'!E5:E13,"To build") -> 3
A19: Deferred | B19: =COUNTIF('1 Events'!F5:F17,"Deferred") -> 4 | C19: =COUNTIF('2 Fields'!H5:H69,"Deferred") -> 18 | D19: =COUNTIF('3 Data model changes'!E5:E13,"Deferred") -> 1
A20: Closed | B20: =COUNTIF('1 Events'!F5:F17,"Closed") -> 1 | C20: =COUNTIF('2 Fields'!H5:H69,"Closed") -> 8 | D20: =COUNTIF('3 Data model changes'!E5:E13,"Closed") -> 4
A21: To build (dates in the build list) | B21: =COUNTIFS('1 Events'!F5:F17,"To build",'1 Events'!G5:G17,"") -> 4 | C21: =COUNTIFS('2 Fields'!H5:H69,"To build",'2 Fields'!I5:I69,"") -> 10 | D21: =COUNTIFS('3 Data model changes'!E5:E13,"To build",'3 Data model changes'!F5:F13,"") -> 3
A22: Total | B22: =COUNTA('1 Events'!F5:F17) -> 13 | C22: =COUNTA('2 Fields'!H5:H69) -> 65 | D22: =COUNTA('3 Data model changes'!E5:E13) -> 9

Sheet 1 Events
A1: Events
A2: One row per event. Status says where it stands; the date is when it was built or the date the owner committed to. Grey rows need nothing in Wave 1A.
A4: ID | B4: Event name | C4: Fired when | D4: Priority | E4: Owner | F4: Status | G4: Built on / due by | H4: What must be built | I4: How to check it is right | J4: Why it is needed | K4: Decided in | L4: Note
A5: E1 | B5: recommendation_request | C5: Any surface asks for a list of items to show | D5: Blocking | E5: Allen; Aravinth for fallback | F5: To build | H5: The service writes one E1 per list it returns, carrying the request_id it returns to SOCO_BE and served_items, the items actually returned. When the fallback ordering is served, SOCO_BE writes E1 itself with policy_id 'delivered' (X-03). | I5: One E1 per served list. Its request_id is the one returned to the app. served_items is present, so unseen items can be derived. | J5: Creates the request identifier that ties everything else together. Without it, no other event can be linked to a decision. | K5: E1, X-03 | L5: Today recommendationrequests is written by getDashboardFeed in feedController.js. Dates: see the build list (ENG-06, APP-15).
A6: E2 | B6: recommendation_impression | C6: An item is at least 50% on screen | D6: Blocking | E6: Aravinth | F6: Built | G6: 46286 | H6: Fired from the existing VisibilityDetector callbacks. One impression per item per request, sent when the item leaves the screen after being seen, or when the app goes to background. Not sent again if the item comes back in the same request. Items served but never seen are not sent. | I6: Scroll a feed: one event per item that was at least 50% on screen, none for items never reached, none repeated within a request. | J6: Records what was shown and in what position. This is the comparison the engine learns from, more than the clicks themselves. | K6: E2, X-04, X-05 | L6: Sent today to POST /feed/impression and written to recommendationimpressions; moves to the single path under X-02 (APP-12). Incognito suppression: APP-04.
A7: E3 | B7: recommendation_click | C7: User taps a card | D7: Blocking | E7: Aravinth | F7: Built | G7: 46286 | H7: A card-level tap that opens post detail (or product detail on a product card) fires E3 alongside the navigation. Taps on like, comment, share or save are E9, not E3. | I7: Tap an item and confirm the event carries the same request_id as the impression for that item. | J7: The positive signal. Only meaningful when paired with the impressions that were not clicked. | K7: E3 | L7: Sent today to POST /feed/click and written to recommendationclicks; moves to the single path under X-02.
A8: E4 | B8: add_to_cart | C8: User adds a product to cart | D8: Important | E8: Aravinth | F8: To build | H8: Fire after every successful cart write, including quantity increases (no 'first add only' rule). Carry request_id from the cart line (X-07) and user_id. | I8: Add the same product twice: two events, each with the quantity added and the request_id of the list the product came from. | J8: Links an add-to-cart to the list that showed the product. The engine uses it to measure the product surface (ENG-26) and for product popularity (ENG-17). | K8: E4, X-07 | L8: Blocked on F20: the cart has no request_id field yet.
A9: E5 | B9: order_placed | C9: Once, on successful order creation, whether or not the order has a post_id. Never on a failed or retried save. | D9: Blocking | E9: Aravinth | F9: To build | H9: Fire once, when an order is successfully created, whether or not it has a post_id. One event per order, never on a failed save. | I9: Place orders with and without a post_id: one event per order in both cases. | J9: The commercial outcome record in ml_events, for the next wave's learned models. In Wave 1A the engine reads orders directly from the orders collection (ENG-03). | K9: E5 | L9: The order fields are built (F24 to F28). The event itself: APP-07.
A10: E6 | B10: order_state_changed | C10: order_status changes | D10: Blocking | E10: Aravinth | F10: To build | H10: Fire after the save from every handler and job that writes order_status: confirm by seller, confirm by user, shipped, delivered, cancel by user, cancel by seller, reject, updateOrderStatus and changePaymentBySeller. Values are order_status values. Returns are read from the order (D1), not sent as E6. | I10: Search the code for every write to order_status, including jobs, and confirm each emits. Counts by state reconcile with the orders collection. | J10: The order state history in ml_events, for the next wave's learned models. In Wave 1A the engine reads order states and returns directly from the orders collection (ENG-03). | K10: E6, X-13 | L10: updateOrderStatus sets any status with no guard, and Payed Off can be reached without Delivered. The engine must not assume states arrive in order.
A11: E7 | B11: payment_state_changed | C11: Payment settles, fails or is charged back | D11: Important | E11: Aravinth | F11: Deferred | H11: Deferred to after Wave 1A. No payment webhook is built for Wave 1A. | I11: — | J11: Separates a completed sale from an abandoned one. | K11: E7 | L11: Consequence: failed payments and chargebacks are not separated. Acceptable because success is order_status Delivered. Payed Off is written by changePaymentBySeller.
A12: E8 | B12: commission_state_changed | C12: Commission is attributed, confirmed or reversed | D12: Blocking | E12: Aravinth | F12: Deferred | H12: Deferred with Engine B. When scheduled: add a 'reversed' value, a timestamp for each transition, and the approve and pay handlers. | I12: — | J12: The outcome signal for promoter matching. | K12: E8 | L12: Records live in influencerearnings: status pending, approved or paid; commission_rate stored per record, default 10.
A13: E9 | B13: social_interaction | C13: Like, unlike, save, unsave, share, repost, follow or unfollow | D13: Important | E13: Aravinth | F13: Built | G13: 46286 | H13: Emitted for every action: like, unlike, save, unsave, share, repost, follow, unfollow. An undo is its own event; the original is never deleted. | I13: All eight actions appear across a sample, each with an actor and a timestamp. | J13: Kept in ml_events as the full record of social actions, including undos, for the next wave's learned models. In Wave 1A the engine reads likes, saves, comments and shares from postevents and follows from follows, so each action is counted once (ENG-03). | K13: E9
A14: E10 | B14: opportunity_state_changed | C14: Promoter accepts, completes, withdraws from or lets an opportunity expire | D14: Blocking | E14: Aravinth | F14: Deferred | H14: Deferred with Engine B. No opportunity flow exists. | I14: — | J14: The outcome signal for promoter to opportunity matching. | K14: E10 | L14: Consequence: promoter-to-opportunity matching has no outcome signal.
A15: E11 | B15: search_performed | C15: User runs a search | D15: Useful | E15: Aravinth | F15: Deferred | H15: Deferred to after Wave 1A. When scheduled, add result_categories. | I15: — | J15: Direct statement of intent, and the strongest signal for a new user with no history. | K15: E11 | L15: Consequence: a new user with no history relies on declared interests only.
A16: E12 | B16: identity_stitched | C16: Anonymous activity is linked to an account at login | D16: Important | E16: Aravinth | F16: Closed | H16: Not needed. Login is required before any feed or product is shown, so there is no anonymous activity to stitch. | I16: — | J16: Would preserve pre-login browsing. | K16: E12
A17: E13 | B17: content_feedback | C17: User chooses not interested, hide, report or mute author on a card | E17: Aravinth | F17: Built | G17: 46286 | H17: Sent when a user chooses not interested, hide, report or mute author. Fields F60 to F65. If a card's menu has no 'Not interested' choice, one is added. | I17: Choose each of the four options on a card: one event each, with the right target_type and feedback_type. | J17: The only negative signal M1 has. | K17: X-12 | L17: Sent to POST /feed/content-feedback and written to contentfeedbacks; moves to the single path under X-02 (APP-12).

Sheet 2 Fields
A1: Fields
A2: One row per field. What the value must be is the rule to build and test against. Grey rows need nothing in Wave 1A.
A4: ID | B4: Event | C4: Field name | D4: Type and example | E4: Priority | F4: Req ref | G4: Owner | H4: Status | I4: Built on / due by | J4: What the value must be | K4: How to check it is right | L4: Why this field is needed | M4: Decided in | N4: Note
A5: F01 | B5: recommendation_request | C5: request_id | D5: string · 3f1c9a2e-7b4d-4e21-9c8a-5d6e7f8a9b0c | E5: Blocking | F5: R1 | G5: Allen | H5: To build | J5: Generated by the recommendation service, one per list, returned in the response and written on E1. | K5: Sample a hundred child events and join back to the request. Zero orphans. | L5: The single identifier that links a request to everything that follows from it | M5: F01 | N5: Built by ENG-06. The app already stores and echoes a request_id (F08).
A6: F02 | B6: recommendation_request | C6: surface | D6: enum · feed | E6: Blocking | F6: R1 | G6: Aravinth; Allen | H6: Built | I6: 46286 | J6: Set by SOCO_BE at the call: feed or product only. products → product; for you, following, trending and local → feed. The service rejects any other value. | K6: Values are only feed or product. No nulls. Set at the call, never inferred. | L6: Which surface asked. Each surface is ranked differently | M6: F02, X-11 | N6: The app also sends home_* tab values; these are not surface values. Only the For You tab calls the service, and SOCO_BE maps it to feed (APP-15). Following, Trending and Local keep their own rules. The service rejects any other surface with 400 (ENG-06).
A7: F03 | B7: recommendation_request | C7: user_id | D7: string · 65f1a2b3c4d5e6f708192a3b | E7: Blocking | F7: R6 | G7: Allen | H7: Closed | J7: No change. Already captured. | K7: Populated on every event from a logged in session, and resolves to a user document. | L7: Who the request was for | M7: F03
A8: F04 | B8: recommendation_request | C8: session_id | D8: string · ses_k2m9q4x1a8b3 | E8: Important | F8: R6 | G8: Aravinth; Allen | H8: To build | J8: The app session id (X-10): generated on app open, kept across restarts, renewed after 30 minutes in background. Passed by SOCO_BE and written on E1. Null until built. | K8: Stable across a visit, including a cold restart. Changes after 30 minutes in background. | L8: Groups activity within one visit | M8: F04, X-10 | N8: Today SessionService mints ses_<12 chars> per app process and sends it on every event, but it is not kept across restarts and not renewed.
A9: F05 | B9: recommendation_request | C9: candidate_ids | D9: array · [6a3fe5cf…7fe, 6a5a79d9…1dd, ...] | E9: Blocking | F9: R2 | G9: Allen | H9: To build | J9: Written on E1 only. Never returned to the app. | K9: Length is at least the number of items shown, and the items shown are all in it. On a small catalogue the two can be equal, which is correct. | L9: What was available to choose from, including items not shown | M9: F05 | N9: Built by ENG-06.
A10: F06 | B10: recommendation_request | C10: policy_id | D10: string · cfg3.interest-2.promoter-1 | E10: Blocking | F10: R3 | G10: Allen; Aravinth | H10: To build | J10: Configuration version plus, on two-method slots, the method that served. SOCO_BE uses 'delivered' on fallback. | K10: Changes when the ranking configuration changes, and the change is timestamped. | L10: Which version of the ranking logic produced this list | M10: F06 | N10: Written today as wave1a_v1. The new format (for example cfg3.interest-2.promoter-1) comes with ENG-05 and ENG-06.
A11: F07 | B11: recommendation_request | C11: server_ts | D11: datetime · 2026-11-04T09:15:22.140Z | E11: Blocking | F11: R7 | G11: Allen | H11: To build | J11: UTC with milliseconds, at decision time. | K11: UTC, ISO 8601, millisecond precision, and not equal to the time the event was ingested. | L11: When the decision was made, in UTC | M11: F07 | N11: Built by ENG-06.
A12: F08 | B12: recommendation_impression | C12: request_id | D12: string · 3f1c9a2e-7b4d-4e21-9c8a-5d6e7f8a9b0c | E12: Blocking | F12: R1 | G12: Aravinth | H12: Built | I12: 46286 | J12: The app stores request_id for each page and sends it on every impression from that page. | K12: Sample a hundred child events and join back to the request. Zero orphans, and no nulls. | L12: Links the impression back to the request | M12: F08, X-07
A13: F09 | B13: recommendation_impression | C13: item_id | D13: string · 6a3fe5cfcce0b0785136e7fe | E13: Blocking | F13: R2 | G13: Aravinth | H13: Built | I13: 46286 | J13: The post or product id from the callback, sent as the 24-character ObjectId string. | K13: Resolves to a post or product document. | L13: Which item was shown | M13: F09
A14: F10 | B14: recommendation_impression | C14: item_type | D14: enum · product | E14: Blocking | F14: R2 | G14: Aravinth | H14: Built | I14: 46286 | J14: post for post cards, product for product cards. No other value in Wave 1A. | K14: Values are only post or product. | L14: Tells the engine what kind of card was shown | M14: F10 | N14: Earlier builds sent promoter, brand or promotion; brand is now rejected.
A15: F11 | B15: recommendation_impression | C15: position | D15: integer · 4 | E15: Blocking | F15: R2 | G15: Aravinth | H15: Built | I15: 46286 | J15: List index + 1 from SliverChildBuilderDelegate, in on-screen order, within each request. Each page is its own request. 0 is rejected. | K15: Integers from 1 upward within a single request, with no gaps in the positions served. Clicked positions need not be consecutive, and click rate need not fall at every position. | L15: Where it appeared. Items at the top get clicked more regardless of quality | M15: F11, X-06
A16: F12 | B16: recommendation_impression | C16: viewport_entered | D16: boolean · true | E16: Blocking | F16: R2 | G16: Aravinth | H16: Built | I16: 46286 | J16: True when at least 50% of the item is on screen, for every media type. Always true on a sent impression. | K16: Every sent row is true. Served-but-unseen items are derived from E1 served_items, not sent. | L16: Whether the user actually saw it | M16: F12, X-04, X-05
A17: F13 | B17: recommendation_impression | C17: dwell_ms | D17: integer · 2400 | E17: Important | F17: R2 | G17: Aravinth | H17: Built | I17: 46286 | J17: Milliseconds of the first spell on screen, sent on leave or app background. A qualified view is at least 3,000 ms. | K17: Positive, and not identical across items in one request. | L17: How long it stayed on screen. A weak signal on its own, useful in combination | M17: F13, X-04
A18: F14 | B18: recommendation_impression | C18: is_exploration | D18: boolean · false | E18: Blocking | F18: R5 | G18: Aravinth | H18: Built | I18: 46286 | J18: Copied from the service response onto every impression from that list. Never computed on the device. | K18: Share of true rows matches the agreed percentage within about one point. | L18: Marks the small randomised slice of traffic | M18: F14
A19: F15 | B19: recommendation_impression | C19: client_ts | D19: datetime · 2026-11-04T14:45:22+05:30 | E19: Important | F19: R7 | G19: Aravinth | H19: Built | I19: 46286 | J19: Device time with timezone offset, taken when the item is first seen. Stored exactly as sent. | K19: Carries a timezone offset and differs from server_ts. Never overwritten by server time. | L19: Device time with offset, kept separate from server time | M19: F15
A20: F16 | B20: recommendation_click | C20: request_id | D20: string · 3f1c9a2e-7b4d-4e21-9c8a-5d6e7f8a9b0c | E20: Blocking | F20: R1 | G20: Aravinth | H20: Built | I20: 46286 | J20: The same stored request_id as the impression for that item. | K20: Sample a hundred child events and join back to the request. Zero orphans, and no nulls. | L20: Links the click to what else was on screen | M20: F16, X-07
A21: F17 | B21: recommendation_click | C21: item_id | D21: string · 6a3fe5cfcce0b0785136e7fe | E21: Blocking | F21: R4 | G21: Aravinth | H21: Built | I21: 46286 | J21: Sent from the card-level tap handler (E3). | K21: Resolves to a post or product document. | L21: What was chosen | M21: F17
A22: F18 | B22: recommendation_click | C22: position | D22: integer · 4 | E22: Blocking | F22: R2 | G22: Aravinth | H22: Built | I22: 46286 | J22: The same index + 1 as F11. | K22: Integers from 1 upward within a single request, with no gaps in the positions served. Clicked positions need not be consecutive, and click rate need not fall at every position. | L22: Position of the clicked item | M22: F18, X-06
A23: F19 | B23: recommendation_click | C23: server_ts | D23: datetime · 2026-11-04T09:15:31.002Z | E23: Blocking | F23: R7 | G23: Aravinth | H23: Built | I23: 46286 | J23: Stamped by SOCO_BE in UTC with milliseconds when it receives the click. | K23: UTC, ISO 8601, millisecond precision, and not equal to the time the event was ingested. | L23: When the click happened | M23: F19
A24: F20 | B24: add_to_cart | C24: request_id | D24: string · 3f1c9a2e-7b4d-4e21-9c8a-5d6e7f8a9b0c | E24: Important | F24: R4 | G24: Aravinth | H24: To build | J24: Stored on the cart line at add time. Null if the product was not reached from a list. | K24: Sample a hundred events from recommended lists and join back to the request: zero orphans. Null only where the action was not reached from a list. | L24: Links the intent back to what prompted it | M24: F20, X-07 | N24: The cart schema has no request_id field yet. Blocks E4 and the request_id chain from cart to order.
A25: F21 | B25: add_to_cart | C25: product_id | D25: string · 6a3fe5cfcce0b0785136e7fe | E25: Important | F25: R4 | G25: Aravinth | H25: Closed | J25: No change. Already captured. | K25: Resolves to a product document. | L25: Which product | M25: F21
A26: F22 | B26: add_to_cart | C26: quantity | D26: integer · 2 | E26: Useful | F26: R4 | G26: Aravinth | H26: To build | J26: The quantity added in this action, sent on every add including increases. | K26: Positive integer. | L26: Strength of intent | M26: F22
A27: F23 | B27: order_placed | C27: order_id | D27: string · 6a48cb8237a8061b26eb067d | E27: Blocking | F27: R4 | G27: Aravinth | H27: Closed | J27: No change. Already captured. | K27: Resolves to an order document, and reconciles one to one with orders created in the same window. | L27: Order identifier | M27: F23
A28: F24 | B28: order_placed | C28: request_id | D28: string · 3f1c9a2e-7b4d-4e21-9c8a-5d6e7f8a9b0c | E28: Blocking | F28: R4 | G28: Aravinth | H28: Built | I28: 46286 | J28: Copied from the cart line, or from product detail on a direct buy, onto the order and the event. Null when not from a list. | K28: Sample a hundred events from recommended lists and join back to the request: zero orphans. Null only where the action was not reached from a list. | L28: Which recommendation led to the order. The single most valuable link in the register | M28: F24, X-07 | N28: orders.request_id exists. The chain through the cart depends on F20.
A29: F25 | B29: order_placed | C29: line_items | D29: array · [{product_id, variant_id, qty, price, base_price}] | E29: Blocking | F29: R4 | G29: Aravinth | H29: Closed | J29: One entry per order, because each order holds one product. Baskets are recovered with checkout_id. No multi-product order is built. | K29: One entry on every order, matching the order's product. | L29: The product, variant, quantity and price on the order | M29: F25 | N29: orders.line_items[] exists (reported 21 Sep).
A30: F26 | B30: order_placed | C30: promoter_id | D30: string · 6a3a6df8bac0b9eb430edc7c | E30: Blocking | F30: R4 | G30: Aravinth | H30: Built | I30: 46286 | J30: The author of the order's post_id, set at order write. Null when post_id is null. No separate promo field. | K30: Populated on orders with a post_id and empty on the rest. | L30: Which promoter, if the order came through a post | M30: F26
A31: F27 | B31: order_placed | C31: order_value | D31: decimal · 2499.00 | E31: Blocking | F31: R4 | G31: Aravinth | H31: Built | I31: 46286 | J31: The order's final amount after discount, read from orders.total_price and sent as order_value. | K31: Matches the order total on the operational record. | L31: Value, for ranking by revenue rather than click count | M31: F27 | N31: The field is total_price, not totalAmount.
A32: F28 | B32: order_placed | C32: server_ts | D32: datetime · 2026-11-04T09:22:10.500Z | E32: Blocking | F32: R7 | G32: Aravinth | H32: Built | I32: 46286 | J32: The order's creation time (orders.created_at), UTC with milliseconds. | K32: UTC, ISO 8601, millisecond precision, and not equal to the time the event was ingested. | L32: When the order was placed | M32: F28
A33: F29 | B33: order_state_changed | C33: order_id | D33: string · 6a48cb8237a8061b26eb067d | E33: Blocking | F33: R4 | G33: Aravinth | H33: Closed | J33: No change. Already captured. | K33: Resolves to an order document, and reconciles one to one with orders created in the same window. | L33: Which order changed | M33: F29
A34: F30 | B34: order_state_changed | C34: new_state | D34: enum · Delivered | E34: Blocking | F34: R4 | G34: Aravinth | H34: To build | J34: The order_status value only (X-13). | K34: Every state written by the app appears at least once. Reconcile against transitions (the steps in tracking_info), not against the orders collection's current status: one order passes through several states. | L34: One canonical state field, usable as an outcome | M34: F30, X-13
A35: F31 | B35: order_state_changed | C35: reason_code | D35: enum · changed_mind | E35: Important | F35: R4 | G35: Aravinth | H35: To build | J35: Required on Cancelled and Rejected, null otherwise, from a closed list. Buyer: changed_mind, ordered_by_mistake, found_better_price, delivery_too_slow, refused_at_delivery. Seller: out_of_stock, cannot_deliver_to_address, pricing_error. System: payment_failed, auto_expired. Any cause: other. Free-text reasons kept as an optional note. Also write cancelled_by as buyer, seller or system. | K35: Present on every Cancelled or Rejected change, null otherwise, and only values from the list. | L35: Why. Separates a product problem from a delivery problem | M35: F31 | N35: Stored in a new reason_code field (DB-04). The existing cancel_reason field stays as the free-text note.
A36: F32 | B36: order_state_changed | C36: state_ts | D36: datetime · 2026-11-09T11:02:00Z | E36: Blocking | F36: R7 | G36: Aravinth | H36: To build | J36: The timestamp already pushed into tracking_info at the status write, sent as state_ts in UTC. | K36: Ordered correctly against the creation time, and reflects when the change happened. | L36: When the state changed, not when the record was written | M36: F32
A37: F33 | B37: payment_state_changed | C37: order_id | D37: string · 6a48cb8237a8061b26eb067d | E37: Important | F37: R4 | G37: Aravinth | H37: Deferred | J37: Deferred with E7. | K37: Resolves to an order document, and reconciles one to one with orders created in the same window. | L37: Which order | M37: F33
A38: F34 | B38: payment_state_changed | C38: new_state | D38: enum · settled | E38: Important | F38: R4 | G38: Aravinth | H38: Deferred | J38: Deferred with E7. | K38: Every terminal state appears at least once. Reconcile counts by state against the orders collection. | L38: Settled, failed or charged back | M38: F34
A39: F35 | B39: payment_state_changed | C39: state_ts | D39: datetime · 2026-11-04T09:23:40Z | E39: Important | F39: R7 | G39: Aravinth | H39: Deferred | J39: Deferred with E7. When built, use Razorpay's own event time. | K39: Ordered correctly against the creation time, and reflects when the change happened. | L39: When | M39: F35
A40: F36 | B40: commission_state_changed | C40: commission_id | D40: string · 6a4c0e11d2a3b4c5d6e7f801 | E40: Blocking | F40: R4 | G40: Aravinth | H40: Deferred | J40: Deferred with E8. | K40: Resolves to a commission record. | L40: Commission record identifier | M40: F36
A41: F37 | B41: commission_state_changed | C41: promoter_id | D41: string · 6a3a6df8bac0b9eb430edc7c | E41: Blocking | F41: R4 | G41: Aravinth | H41: Deferred | J41: Deferred with E8. When built, send influencer_id as promoter_id. | K41: Populated on every commission record. | L41: Which promoter earned it | M41: F37
...

Sheet 3 Data model changes
A1: Data model changes
A2: Changes to the database itself rather than to an event.
A4: ID | B4: Item | C4: Priority | D4: Owner | E4: Status | F4: Built on / due by | G4: What is needed | H4: Consequence if not done | I4: Decided in | J4: Note
A5: D1 | B5: Return capture on the order | C5: Blocking | D5: Aravinth | E5: To build | G5: Add return_requested (true or false, default false) and return_requested_at (date) to the order, and a 'Request return' control in order history once an order is Delivered. return_type from a closed list: wrong_item, quality, size, not_as_described, changed_mind, damaged. Collection, refund and seller workflow stay offline. | H5: A returned order looks like a successful one, and every commerce label counts returns as sales. | I5: D1
A6: D2 | B6: One canonical order status | C6: Blocking | D6: Aravinth | E6: Closed | G6: order_status is authoritative. The only remaining action is X-13. | H6: No agreed definition of a successful order. | I6: D2, X-13 | J6: The remaining action is APP-09.
A7: D3 | B7: Shared checkout identifier | C7: Blocking | D7: Aravinth | E7: Verify | G7: checkout_id on every order from one checkout. Verified as F59. | H7: Items bought together cannot be identified, so the co-purchase method cannot be built. | I7: D3, F59 | J7: Basket-of-three check still to run.
A8: D4 | B8: Campaign entity | C8: Blocking | D8: Aravinth | E8: Deferred | G8: Deferred with Engine C. | H8: Campaigns cannot be measured or attributed. | I8: D4
A9: D5 | B9: Promoter and influencer as account states | C9: Important | D9: Aravinth | E9: Closed | G9: Not needed under the promoter continuum. The engine keeps the score and its history. | H9: — | I9: D5 | J9: Not needed: the promoter score is a continuum.
A10: D6 | B10: Timestamped social interactions | C10: Important | D10: Aravinth | E10: Closed | G10: Closed by E9: each interaction is its own timestamped event. Counters on posts stay as they are. | H10: — | I10: D6, E9
A11: D7 | B11: Stable identifiers | C11: Important | D11: Aravinth | E11: Closed | G11: MongoDB ids are never reused. | H11: User and item histories fragment silently. | I11: D7 | J11: MongoDB ids are never reused, so nothing to build.
A12: D8 | B12: Raw event retention | C12: Important | D12: Aravinth; Allen for ml_events | E12: To build | G12: Raw events kept at least 12 months (X-08). postevents has no expiry. The 90-day expiry on the recommendation collections, including contentfeedbacks, is raised to 365 days. userevents is marked deprecated in code. | H12: Training windows are truncated and seasonal patterns cannot be learned. | I12: D8, X-08 | J12: postevents confirmed with no expiry. The 365-day change and the userevents marking: DB-01.
A13: D9 | B13: Incognito activity excluded | C13: Important | D13: Aravinth; Allen for the order filter | E13: To build | G13: As X-09: no recommendation or engagement events while in incognito, and incognito orders ignored for learning. | H13: Incognito activity is learned from and shown back to the user: a privacy exposure as well as a modelling defect. | I13: D9, X-09 | J13: Today incognito covers ordering only; feed events are still sent.

Sheet Rules
A1: Rules
A2: Standing rules that apply across many rows. Rows point here in the Decided in column.
A4: Ref | B4: Rule | C4: What it says | D4: Owner | E4: Note
A5: X-01 | B5: Owner of client-side events | C5: Aravinth owns E2, E3 and E13, as the contact for the Flutter app. | D5: Aravinth
A6: X-02 | B6: One event path | C6: Every event travels Flutter → SOCO_BE → POST /v1/events → ml_events. Flutter never calls the engine directly. SOCO_BE has one client-facing route that receives E2, E3 and E13 and forwards them in batches. recommendationrequests, recommendationimpressions, recommendationclicks, recommendationengagements and contentfeedbacks stop being an engine source once /v1/events is live; until then they keep being written. | D6: Aravinth (route); Allen (ingest) | E6: Built by APP-12 (route) and ENG-04 (ingest).
A7: X-03 | B7: Every feed list emits events | C7: Every list on the feed surface emits the events, whether the engine or the fallback produced it. Fallback lists carry policy_id 'delivered'. postevents continues to be written for Influencer Analytics (APP-02 and APP-03 change two of its fields). | D7: Aravinth | E7: Built by APP-15 (fallback lists).
A8: X-04 | B8: Seen, and a qualified view | C8: Seen means at least 50% of the item is on screen, for every media type. A qualified view is seen and on screen for at least 3,000 ms. Video play and pause thresholds are separate. | D8: Aravinth
A9: X-05 | B9: When an impression is sent | C9: One impression per item per request, sent on leave or app background, with dwell_ms for the first spell. Not resent in the same request. Unseen items are not sent; they come from E1 served_items. | D9: Aravinth
A10: X-06 | B10: Position numbering | C10: Position counts from 1, in on-screen order, within each request. Each page is its own request. 0 is rejected. | D10: Aravinth
A11: X-07 | B11: How request_id travels | C11: request_id travels with the item: card → product detail → cart line → order. Any action not reached from a recommended list sends null. | D11: Aravinth | E11: The cart step: DB-05 and APP-05.
A12: X-08 | B12: Retention of raw events | C12: Raw events kept at least 12 months. ml_events has no expiry under 365 days. The recommendation collections, including contentfeedbacks, keep 365 days while they remain a source. postevents has no expiry. No expiry is added to an event collection unless Allen and Aravinth agree in writing. | D12: Aravinth; Allen for ml_events | E12: The change: DB-01.
A13: X-09 | B13: Incognito | C13: In incognito the app sends no E2, E3, E4, E9 or E13. Orders with isIncognitoMode emit no E5 or E6. The engine ignores incognito orders for recommendations and profiles; the fraud rules still read them. No new incognito field. | D13: Aravinth; Allen for the order filter | E13: Built by APP-04 (app) and ENG-10 (engine order filter).
A14: X-10 | B14: App session identifier | C14: One app session id, minted by the app's SessionService (ses_…) when the app opens, kept across restarts, and renewed after 30 minutes in background. SOCO_BE passes it on the request; the service writes it on E1 as session_id. user_sessions is a login and device tracker and is not this identifier. | D14: Aravinth | E14: Built by APP-01. The appsessions collection exists but is not used for this.
A15: X-11 | B15: Launch surfaces | C15: Wave 1A surfaces are feed (the home feed) and product (product detail and cart). No opportunity surface. If both cannot launch together, feed goes first. | D15: Aravinth
A16: X-12 | B16: Content feedback event | C16: E13 content_feedback is sent on not interested, hide, report or mute author. Fields F60 to F65. | D16: Aravinth
A17: X-13 | B17: One order status field | C17: E6 reads order_status only. When order_status becomes Delivered, seller_delivery_status is written in the same save. Other status fields stay for operations and are not read by the engine. | D17: Aravinth | E17: Built by APP-09. order_status has no transition guard, so the engine never assumes states arrive in order.
A18: X-14 | B18: Attribution fields on postevents | C18: Each attribution field on postevents is filled only on the event types below. Everywhere else it is null by design. - product_id: cart add and purchase events only, the product in that action. Null on likes, comments and shares, because the post's products list already holds them. - order_id: purchase events only, the order created. - session_id: every event, the app session id from X-10. Null until X-10 is built. - referral_code: not filled in Wave 1A. The referral feature is not built. - view_duration_seconds: view events only, the same on-screen time as E2 dwell_ms, in seconds. Required on every view. The engine uses it to decide qualified views (3 seconds or more), and Influencer Analytics reads it too. - viewer_city, viewer_gender, viewer_district: not filled in Wave 1A. The engine takes demographics from the user profile. Filling them for Influencer Analytics is a separate decision for SOCO, including consent. | D18: Aravinth | E18: Added 22 Sep 2026. Only product_id, order_id and session_id need code; the rest are blank on purpose. On 11 Sep, order_id was filled on every purchase and product_id on purchases and cart adds, so if they read null now, check for a regression.
A19: X-15 | B19: Exploration slice | C19: is_exploration is set by the service and copied by the app, on 5% of feed requests. There is no shadow mode. | D19: Allen
