Workbook

Sheet Read me
A1: Capture register (SOCO-REC-DS-003a)
A3: What this is | B3: The single list of what the app, the backend and the recommendation service must capture, field by field. Updated 14 October 2026. The Wave 1A build list wins where the two differ. | H3: Aravinth | I3: For each of your rows, "What must be built" / "What the value must be" is the rule you have to code to. "How to check it is right" is how you will check your own work.
A4: What is in it | B4: 13 events, 86 fields and 12 data model changes, the Rules sheet that most rows point to, and sheet 4, which maps the platform's 26 native event types to the events. | H4: Allen | I4: Builds your rows (E1, served_items, the engine sync, ml_events) the same way, and reports status the same way.
A5: How to read a row | B5: Status says where it stood on 14 October 2026 (Verify = reported built in the APP-00 answers, check still to run). For a built row, Built on / due by is the build date. For rows still to build it is blank: the step each row sits in is in the Wave 1A build list, which also names the item (APP, DB or ENG) that builds it. What must be built / What the value must be is the rule to build and test against. Decided in lists the related codes in this register. | I5: Run the code test. The test reads the register. Generate the schema file both sides build against from it.
A6: Built | B6: Reported built. Checked by the How to check column. | I6: Report failures in two kinds: names missing from the register, or the test not being able to read the layout.
A7: Verify | B7: Reported built, one check still to run. | H7: Aravinth | I7: Keeps the register in step with the build list: dates every change in the Note, and adds rows only for new fields in the API contract.
A8: To build | B8: Accepted, not built yet. The step is in the Wave 1A build list.
A9: Deferred | B9: After Wave 1A. The consequence is in the Note.
A10: Closed | B10: Nothing to build: already captured or not needed.
A11: Changing a row | B11: Change it here and date the change in the Note. Any change to an event, a field or a retention period is agreed in writing by Allen and Aravinth first.
A12: History | B12: Earlier versions are withdrawn. This is the only version.
A14: Where things stand
A15: Status | B15: Events | C15: Fields | D15: Data model changes
A16: Built | B16: =COUNTIF('1 Events'!F5:F17,"Built") | C16: =COUNTIF('2 Fields'!H5:H90,"Built") | D16: =COUNTIF('3 Data model changes'!E5:E16,"Built")
A17: Verify | B17: =COUNTIF('1 Events'!F5:F17,"Verify") | C17: =COUNTIF('2 Fields'!H5:H90,"Verify") | D17: =COUNTIF('3 Data model changes'!E5:E16,"Verify")
A18: To build | B18: =COUNTIF('1 Events'!F5:F17,"To build") | C18: =COUNTIF('2 Fields'!H5:H90,"To build") | D18: =COUNTIF('3 Data model changes'!E5:E16,"To build")
A19: Deferred | B19: =COUNTIF('1 Events'!F5:F17,"Deferred") | C19: =COUNTIF('2 Fields'!H5:H90,"Deferred") | D19: =COUNTIF('3 Data model changes'!E5:E16,"Deferred")
A20: Closed | B20: =COUNTIF('1 Events'!F5:F17,"Closed") | C20: =COUNTIF('2 Fields'!H5:H90,"Closed") | D20: =COUNTIF('3 Data model changes'!E5:E16,"Closed")
A21: To build (dates in the build list) | B21: =COUNTIFS('1 Events'!F5:F17,"To build",'1 Events'!G5:G17,"") | C21: =COUNTIFS('2 Fields'!H5:H90,"To build",'2 Fields'!I5:I90,"") | D21: =COUNTIFS('3 Data model changes'!E5:E16,"To build",'3 Data model changes'!F5:F16,"")
A22: Total | B22: =COUNTA('1 Events'!F5:F17) | C22: =COUNTA('2 Fields'!H5:H90) | D22: =COUNTA('3 Data model changes'!E5:E16)

Sheet 1 Events
A1: Events
A2: One row per event. Status says where it stands; the date is when it was built or the date the owner committed to. Grey rows need nothing in Wave 1A.
A4: ID | B4: Event name | C4: Fired when | D4: Priority | E4: Owner | F4: Status | G4: Built on / due by | H4: What must be built | I4: How to check it is right | J4: Why it is needed | K4: Decided in | L4: Note
A5: E1 | B5: recommendation_request | C5: Any surface asks for a list of items to show | D5: Blocking | E5: Allen; Aravinth for fallback lists and the serve log | F5: To build | H5: The service writes one E1 per list it returns, in the engine database, with served_items (item_id, item_type, post_id, product_id, position). SOCO_BE writes recommendationrequests for fallback lists (platform policy_id), and one rec_serve_log row per list request (origin, outcome, elapsed time). The engine sync copies both (X-02). | I5: One E1 per engine list, and one rec_serve_log row per list request. At least 99% of impressions on engine lists show the item the engine returned at that position (build list ENG-23 V9). | J5: Creates the request identifier that ties everything else together. Without it, no other event can be linked to a decision. | K5: E1, X-03 | L5: 29 Sep 2026: Engine lists are shown unchanged: no delivered-list record (X-17). Build list ENG-06 (E1) and APP-15 (serve log).
A6: E2 | B6: recommendation_impression | C6: An item is at least 50% on screen | D6: Blocking | E6: Aravinth | F6: Built | G6: 46286 | H6: Recorded by SOCO_BE as a postevents impression row from the app's batches. One per item per list, sent when the item leaves the screen after being seen, or when the app goes to background, with dwell_ms of the first spell. Not sent again in the same list. Unseen items are not sent. An impression on the post page (surface post_detail) is a page visit, never a card impression or a seen_ids entry. | I6: Scroll a feed: one event per item that was at least 50% on screen, none for items never reached, none repeated within a request. | J6: Records what was shown and in what position. This is the comparison the engine learns from, more than the clicks themselves. | K6: E2, X-04, X-05 | L6: 28 Sep 2026: Native event: impression (capture register sheet 4). The engine reads it with its sync (X-02). Post-page check: build list APP-00 point 5.
A7: E3 | B7: recommendation_click | C7: User taps a card | D7: Blocking | E7: Aravinth | F7: Built | G7: 46286 | H7: A card-level tap that opens post detail (or product detail on a product card) fires E3 alongside the navigation. Taps on like, comment, share or save are E9, not E3. | I7: Tap an item and confirm the event carries the same request_id as the impression for that item. | J7: The positive signal. Only meaningful when paired with the impressions that were not clicked. | K7: E3 | L7: 28 Sep 2026: Native event: click (product_click from older builds counts as a click). Read by the engine sync (X-02).
A8: E4 | B8: add_to_cart | C8: User adds a product to cart | D8: Important | E8: Aravinth | F8: Verify | H8: Recorded by SOCO_BE after every cart write: add_to_cart for units added and remove_from_cart for units removed, each with variant_id, quantity (units in this action), value and the list that first added the item (carts.ml, X-07). | I8: Add a product, raise it to 3, lower it to 2, remove it: two add rows (1 and 2 units) and two remove rows (1 and 2 units), all with the first list. | J8: Links an add-to-cart to the list that showed the product. The engine uses it to measure the product surface (ENG-26) and for product popularity (ENG-17). | K8: E4, X-07 | L8: 28 Sep 2026: Reported built (APP-00 answers Q4). remove_from_cart is stored but carries no model weight in Wave 1A. Build list APP-06.
A9: E5 | B9: order_placed | C9: Once, on successful order creation, whether or not the order has a post_id. Never on a failed or retried save. | D9: Blocking | E9: Aravinth | F9: Verify | H9: One purchase row in postevents per order, and the order itself, on successful creation, with or without a post. Incognito orders are recorded too (X-09). | I9: Place orders with and without a post_id: one event per order in both cases. | J9: The commercial outcome record in ml_events, for the next wave's learned models. In Wave 1A the engine reads orders directly from the orders collection (ENG-03). | K9: E5 | L9: 28 Sep 2026: Reported built (answers Q5, Q11). Build list APP-07.
A10: E6 | B10: order_state_changed | C10: order_status changes, or another order history event is written (payment, return request, refund) | D10: Blocking | E10: Aravinth | F10: Verify | H10: Nothing new to build. Two things are kept apart. The order's current state is orders.order_status. The order's history is orders.tracking_info (existing): one entry per business event, in time order, each with a free-text status and a timestamp (some also a reason), and no event code or actor. Some history events change order_status (accepted, shipped, delivered, cancelled, returned) and some do not (payment, return request, refund). The engine maps each entry to a history event and always takes outcomes from order_status (build list ENG-30 point 5). Returns: there is no Return Requested status. A buyer's request creates a returnrequests record and a 'Return requested' history entry while order_status stays Delivered; the seller's return sets order_status Returned and return_info.returned_at (D1). | I10: Every code path that writes order_status adds a tracking_info entry. Every entry text maps to a history event, and the engine's daily reconciliation finds no unmatched or contradictory history. The database side was observed on order 6a9fac747498f914bd4a50c8 on 14 Oct 2026 (build list ENG-23 V8). | J10: The order state history in ml_events, for the next wave's learned models. In Wave 1A the engine reads order states and returns directly from the orders collection (ENG-03). | K10: E6, X-13, X-18, X-23 | L10: 14 Oct 2026: Verified on the platform database (order 6a9fac747498f914bd4a50c8): entries are text plus timestamp, with no actor, so 'who acted' is dropped. Build list APP-08, ENG-30. 29 Sep 2026: tracking_info replaces the status log; entries are added only where a code path writes none. Build list APP-08.
A11: E7 | B11: payment_state_changed | C11: Payment settles, fails or is charged back | D11: Important | E11: Aravinth | F11: Deferred | H11: Deferred to after Wave 1A. No payment webhook is built for Wave 1A. | I11: — | J11: Separates a completed sale from an abandoned one. | K11: E7 | L11: Consequence: failed payments and chargebacks are not separated. Acceptable because success is order_status Delivered. Payed Off is written by changePaymentBySeller.
A12: E8 | B12: commission_state_changed | C12: A commission is recorded, approved, paid, reversed or rejected | D12: Blocking | E12: Aravinth | F12: Deferred | H12: Deferred: no Wave 1A model reads it. The platform records commission in commissiontransactions (one row per earner per order) and commissionledgers (one per order); influencerearnings is no longer written or read. When scheduled, the engine copies commissiontransactions (F36 to F41). | I12: — | J12: The outcome signal for promoter matching. | K12: E8 | L12: 14 Oct 2026: Statuses: pending, approved, paid, reversed, rejected. Rejected is final; a reversal after payment creates a clawback. statusHistory, approvedAt, paidAt and reversedAt are kept (App Team ML Reference, 8 Oct, sections 8.4 and 8.7; answers of 13 Oct, Q3 to Q5).
A13: E9 | B13: social_interaction | C13: Like, unlike, save, unsave, share, repost, follow or unfollow | D13: Important | E13: Aravinth | F13: Built | G13: 46286 | H13: Recorded by SOCO_BE as postevents rows: like, unlike, save, unsave, comment, uncomment, share, repost, follow, unfollow. An undo is its own row with undo_of; the original gets undone_at and is never deleted. is_self marks the author acting on their own post. | I13: All eight actions appear across a sample, each with an actor and a timestamp. | J13: Kept in ml_events as the full record of social actions, including undos, for the next wave's learned models. In Wave 1A the engine reads likes, saves, comments and shares from postevents and follows from follows, so each action is counted once (ENG-03). | K13: E9 | L13: 28 Sep 2026: Native events (sheet 4). Read by the engine sync.
A14: E10 | B14: opportunity_state_changed (collaboration) | C14: A brand and creator collaboration changes state | D14: Blocking | E14: Aravinth | F14: Deferred | H14: Deferred: no Wave 1A model reads it. The platform records collaboration outcomes in collaborations and collaborationevents (invited, pitched, countered, accepted, declined, withdrawn, expired, started, completed, cancelled and others). When scheduled, the engine copies collaborationevents (F47 to F51). | I14: — | J14: The outcome signal for promoter to brand matching. | K14: E10 | L14: 14 Oct 2026: 'No opportunity flow exists' removed (App Team ML Reference, 8 Oct, section 7). A collaboration is one store with one creator; a multi-creator campaign does not exist, so D4 stays Deferred. What a brand or creator was shown in discovery is not logged (ML Reference section 13).
A15: E11 | B15: search_performed | C15: User runs a search | D15: Useful | E15: Aravinth | F15: Deferred | H15: Deferred to after Wave 1A. When scheduled, add result_categories. | I15: — | J15: Direct statement of intent, and the strongest signal for a new user with no history. | K15: E11 | L15: Consequence: a new user with no history relies on declared interests only.
A16: E12 | B16: identity_stitched | C16: Anonymous activity is linked to an account at login | D16: Important | E16: Aravinth | F16: Closed | H16: Not needed. Login is required before any feed or product is shown, so there is no anonymous activity to stitch. | I16: — | J16: Would preserve pre-login browsing. | K16: E12
A17: E13 | B17: content_feedback | C17: User chooses not interested, hide, report or mute author on a card | E17: Aravinth | F17: Built | G17: 46286 | H17: Sent when a user chooses not interested, hide, report or mute author. Fields F60 to F65. If a card's menu has no 'Not interested' choice, one is added. | I17: Choose each of the four options on a card: one event each, with the right target_type and feedback_type. | J17: The only negative signal M1 has. | K17: X-12 | L17: 28 Sep 2026: Native event: feedback, with feedback_type and target_type. Read by the engine sync.

Sheet 2 Fields
A1: Fields
A2: One row per field. What the value must be is the rule to build and test against. Grey rows need nothing in Wave 1A.
A4: ID | B4: Event | C4: Field name | D4: Type and example | E4: Priority | F4: Req ref | G4: Owner | H4: Status | I4: Built on / due by | J4: What the value must be | K4: How to check it is right | L4: Why this field is needed | M4: Decided in | N4: Note
A5: F01 | B5: recommendation_request | C5: request_id | D5: string · 3f1c9a2e-7b4d-4e21-9c8a-5d6e7f8a9b0c | E5: Blocking | F5: R1 | G5: Allen | H5: To build | J5: Generated by the recommendation service, one per list, returned in the response and written on E1. | K5: Sample a hundred child events and join back to the request. Zero orphans. | L5: The single identifier that links a request to everything that follows from it | M5: F01 | N5: Built by ENG-06. The app already stores and echoes a request_id (F08).
A6: F02 | B6: recommendation_request | C6: surface | D6: enum · feed | E6: Blocking | F6: R1 | G6: Aravinth; Allen | H6: Built | I6: 46286 | J6: Set by SOCO_BE at the call: feed or product only. products → product; for you, following, trending and local → feed. The service rejects any other value. | K6: Values are only feed or product. No nulls. Set at the call, never inferred. | L6: Which surface asked. Each surface is ranked differently | M6: F02, X-11 | N6: 28 Sep 2026: Platform rows carry native surfaces (home_for_you, product_detail, cart, post_detail). The engine maps home_for_you to feed and product_detail and cart to product. Other tabs and post_detail are not engine surfaces.
A7: F03 | B7: recommendation_request | C7: user_id | D7: string · 65f1a2b3c4d5e6f708192a3b | E7: Blocking | F7: R6 | G7: Allen | H7: Closed | J7: No change. Already captured. | K7: Populated on every event from a logged in session, and resolves to a user document. | L7: Who the request was for | M7: F03
A8: F04 | B8: recommendation_request | C8: session_id | D8: string · ses_k2m9q4x1a8b3 | E8: Important | F8: R6 | G8: Aravinth; Allen | H8: Verify | J8: The app session id (X-10): kept across restarts; a new one after 30 minutes or more away (background or closed); does not expire during use. Passed by SOCO_BE and written on E1. | K8: Stable across a visit, including a cold restart. Changes after 30 minutes in background. | L8: Groups activity within one visit | M8: F04, X-10 | N8: 28 Sep 2026: Reported built (answers Q14). Device check: build list APP-01.
A9: F05 | B9: recommendation_request | C9: candidate_ids | D9: array · [6a3fe5cf…7fe, 6a5a79d9…1dd, ...] | E9: Blocking | F9: R2 | G9: Allen | H9: To build | J9: Written on E1 only. Never returned to the app. | K9: Length is at least the number of items shown, and the items shown are all in it. On a small catalogue the two can be equal, which is correct. | L9: What was available to choose from, including items not shown | M9: F05 | N9: Built by ENG-06.
A10: F06 | B10: recommendation_request | C10: policy_id | D10: string · cfg3.interest-2.promoter-1 | E10: Blocking | F10: R3 | G10: Allen; Aravinth | H10: To build | J10: Engine lists: configuration version plus, on two-method slots, the method that served (cfg…). Fallback lists keep the platform's own policy_id (wave1a_v1 or prodrec_v1). | K10: Changes when the ranking configuration changes, and the change is timestamped. | L10: Which version of the ranking logic produced this list | M10: F06 | N10: 28 Sep 2026: Any policy_id not starting with cfg is a fallback list.
A11: F07 | B11: recommendation_request | C11: server_ts | D11: datetime · 2026-11-04T09:15:22.140Z | E11: Blocking | F11: R7 | G11: Allen | H11: To build | J11: UTC with milliseconds, at decision time. | K11: UTC, ISO 8601, millisecond precision, and not equal to the time the event was ingested. | L11: When the decision was made, in UTC | M11: F07 | N11: Built by ENG-06.
A12: F08 | B12: recommendation_impression | C12: request_id | D12: string · 3f1c9a2e-7b4d-4e21-9c8a-5d6e7f8a9b0c | E12: Blocking | F12: R1 | G12: Aravinth | H12: Built | I12: 46286 | J12: The app stores request_id for each page and sends it on every impression from that page. | K12: Sample a hundred child events and join back to the request. Zero orphans, and no nulls. | L12: Links the impression back to the request | M12: F08, X-07
A13: F09 | B13: recommendation_impression | C13: item_id | D13: string · 6a3fe5cfcce0b0785136e7fe | E13: Blocking | F13: R2 | G13: Aravinth | H13: Built | I13: 46286 | J13: The id of the card shown, as the 24-character ObjectId string: a post id on a post card (including a post that shows a product), a product id on a product card. post_id and product_id are kept alongside (F75). | K13: Resolves to a post or product document. | L13: Which item was shown | M13: F09
A14: F10 | B14: recommendation_impression | C14: item_type | D14: enum · product | E14: Blocking | F14: R2 | G14: Aravinth | H14: Built | I14: 46286 | J14: post for post cards, product for product cards. No other value in Wave 1A. | K14: Values are only post or product. | L14: Tells the engine what kind of card was shown | M14: F10 | N14: 28 Sep 2026: On platform feed lists, item_type product with a post id is a post card showing a product: read post_id = item_id (X-16).
A15: F11 | B15: recommendation_impression | C15: position | D15: integer · 4 | E15: Blocking | F15: R2 | G15: Aravinth | H15: Built | I15: 46286 | J15: From 1, in on-screen order, within each request. Each page is its own request. 0 is invalid. SOCO_BE shows engine lists unchanged, so this is the position the engine returned. | K15: Integers from 1 upward within a single request, with no gaps in the positions served. Clicked positions need not be consecutive, and click rate need not fall at every position. | L15: Where it appeared. Items at the top get clicked more regardless of quality | M15: F11, X-06 | N15: 29 Sep 2026: X-06. engine_position is no longer needed.
A16: F12 | B16: recommendation_impression | C16: viewport_entered | D16: boolean · true | E16: Blocking | F16: R2 | G16: Aravinth | H16: Built | I16: 46286 | J16: True when at least 50% of the item is on screen, for every media type. Always true on a sent impression. | K16: Every sent row is true. Served-but-unseen items are derived from E1 served_items, not sent. | L16: Whether the user actually saw it | M16: F12, X-04, X-05
A17: F13 | B17: recommendation_impression | C17: dwell_ms | D17: integer · 2400 | E17: Important | F17: R2 | G17: Aravinth | H17: Built | I17: 46286 | J17: Milliseconds of the first spell on screen, sent on leave or app background. A qualified view is at least 3,000 ms. | K17: Positive, and not identical across items in one request. | L17: How long it stayed on screen. A weak signal on its own, useful in combination | M17: F13, X-04 | N17: 28 Sep 2026: On view rows, dwell_ms is the longest first-spell watch (never lowered) or the time on the post page; it replaces view_duration_seconds. Capped at 600,000 ms.
A18: F14 | B18: recommendation_impression | C18: is_exploration | D18: boolean · false | E18: Blocking | F18: R5 | G18: Aravinth | H18: Built | I18: 46286 | J18: Copied from the service response onto every impression from that list. Never computed on the device. | K18: Share of true rows matches the agreed percentage within about one point. | L18: Marks the small randomised slice of traffic | M18: F14
A19: F15 | B19: recommendation_impression | C19: client_ts | D19: datetime · 2026-11-04T14:45:22+05:30 | E19: Important | F19: R7 | G19: Aravinth | H19: Built | I19: 46286 | J19: Device time with timezone offset, taken when the item is first seen. Stored exactly as sent. | K19: Carries a timezone offset and differs from server_ts. Never overwritten by server time. | L19: Device time with offset, kept separate from server time | M19: F15
A20: F16 | B20: recommendation_click | C20: request_id | D20: string · 3f1c9a2e-7b4d-4e21-9c8a-5d6e7f8a9b0c | E20: Blocking | F20: R1 | G20: Aravinth | H20: Built | I20: 46286 | J20: The same stored request_id as the impression for that item. | K20: Sample a hundred child events and join back to the request. Zero orphans, and no nulls. | L20: Links the click to what else was on screen | M20: F16, X-07
A21: F17 | B21: recommendation_click | C21: item_id | D21: string · 6a3fe5cfcce0b0785136e7fe | E21: Blocking | F21: R4 | G21: Aravinth | H21: Built | I21: 46286 | J21: Sent from the card-level tap handler (E3). | K21: Resolves to a post or product document. | L21: What was chosen | M21: F17
A22: F18 | B22: recommendation_click | C22: position | D22: integer · 4 | E22: Blocking | F22: R2 | G22: Aravinth | H22: Built | I22: 46286 | J22: The same displayed position as F11. | K22: Integers from 1 upward within a single request, with no gaps in the positions served. Clicked positions need not be consecutive, and click rate need not fall at every position. | L22: Position of the clicked item | M22: F18, X-06
A23: F19 | B23: recommendation_click | C23: server_ts | D23: datetime · 2026-11-04T09:15:31.002Z | E23: Blocking | F23: R7 | G23: Aravinth | H23: Built | I23: 46286 | J23: Stamped by SOCO_BE in UTC with milliseconds when it receives the click. | K23: UTC, ISO 8601, millisecond precision, and not equal to the time the event was ingested. | L23: When the click happened | M23: F19
A24: F20 | B24: add_to_cart | C24: request_id | D24: string · 3f1c9a2e-7b4d-4e21-9c8a-5d6e7f8a9b0c | E24: Important | F24: R4 | G24: Aravinth | H24: Verify | J24: The list that first put the item in the cart, kept in carts.ml.request_id (with position, surface, item_type, is_exploration, at). Quantity changes, removal and an order without context carry it; a re-add from another list is credited to that list. Null if the item was not reached from a list. | K24: Sample a hundred events from recommended lists and join back to the request: zero orphans. Null only where the action was not reached from a list. | L24: Links the intent back to what prompted it | M24: F20, X-07 | N24: 28 Sep 2026: Reported built (answers Q4). X-07.
A25: F21 | B25: add_to_cart | C25: product_id | D25: string · 6a3fe5cfcce0b0785136e7fe | E25: Important | F25: R4 | G25: Aravinth | H25: Closed | J25: No change. Already captured. | K25: Resolves to a product document. | L25: Which product | M25: F21
A26: F22 | B26: add_to_cart | C26: quantity | D26: integer · 2 | E26: Useful | F26: R4 | G26: Aravinth | H26: Verify | J26: Units in this action: added on add_to_cart, removed on remove_from_cart. | K26: Positive integer. | L26: Strength of intent | M26: F22 | N26: 28 Sep 2026: Reported built.
A27: F23 | B27: order_placed | C27: order_id | D27: string · 6a48cb8237a8061b26eb067d | E27: Blocking | F27: R4 | G27: Aravinth | H27: Closed | J27: No change. Already captured. | K27: Resolves to an order document, and reconciles one to one with orders created in the same window. | L27: Order identifier | M27: F23
A28: F24 | B28: order_placed | C28: request_id | D28: string · 3f1c9a2e-7b4d-4e21-9c8a-5d6e7f8a9b0c | E28: Blocking | F28: R4 | G28: Aravinth | H28: Built | I28: 46286 | J28: Copied from the cart line, or from product detail on a direct buy, onto the order and the event. Null when not from a list. | K28: Sample a hundred events from recommended lists and join back to the request: zero orphans. Null only where the action was not reached from a list. | L28: Which recommendation led to the order. The single most valuable link in the register | M28: F24, X-07 | N28: orders.request_id exists. The chain through the cart depends on F20.
A29: F25 | B29: order_placed | C29: line_items | D29: array · [{product_id, variant_id, qty, price, base_price}] | E29: Blocking | F29: R4 | G29: Aravinth | H29: Closed | J29: One entry per order, because each order holds one product: product_id, variant_id, qty, price, base_price. orders.variant_id holds the same variant at the top level. Baskets are recovered with checkout_id. | K29: One entry on every order, matching the order's product. | L29: The product, variant, quantity and price on the order | M29: F25 | N29: 28 Sep 2026: variant_id reported fixed (answers Q11). The order wins over the event for the variant bought.
A30: F26 | B30: order_placed | C30: promoter_id | D30: string · 6a3a6df8bac0b9eb430edc7c (text, user or store) | E30: Blocking | F30: R4 | G30: Aravinth | H30: Built | I30: 46286 | J30: The author of the order's post_id (posts.userId), set at order write and stored as text. It can be a user or a store. Null when post_id is null. Orders created before 23 September 2026 have none: the engine takes the post's author instead (build list ENG-30). No separate promo field. | K30: Populated on orders with a post_id created from 23 September 2026, and empty on direct orders. | L30: Which promoter, if the order came through a post | M30: F26 | N30: 14 Oct 2026: Confirmed by the App Team (answers of 13 Oct, Q1). No backfill: older rows are test data.
A31: F27 | B31: order_placed | C31: order_value | D31: decimal · 2499.00 | E31: Blocking | F31: R4 | G31: Aravinth | H31: Built | I31: 46286 | J31: The order's final amount after discount, read from orders.total_price and sent as order_value. | K31: Matches the order total on the operational record. | L31: Value, for ranking by revenue rather than click count | M31: F27 | N31: The field is total_price, not totalAmount.
A32: F28 | B32: order_placed | C32: server_ts | D32: datetime · 2026-11-04T09:22:10.500Z | E32: Blocking | F32: R7 | G32: Aravinth | H32: Built | I32: 46286 | J32: The order's creation time (orders.created_at), UTC with milliseconds. | K32: UTC, ISO 8601, millisecond precision, and not equal to the time the event was ingested. | L32: When the order was placed | M32: F28
A33: F29 | B33: order_state_changed | C33: order_id | D33: string · 6a48cb8237a8061b26eb067d | E33: Blocking | F33: R4 | G33: Aravinth | H33: Closed | J33: No change. Already captured. | K33: Resolves to an order document, and reconciles one to one with orders created in the same window. | L33: Which order changed | M33: F29
A34: F30 | B34: order_state_changed | C34: history event (tracking_info entry status, free text) | D34: string · Delivered (Urban Vogue Fashion Studio) | E34: Blocking | F34: R4 | G34: Aravinth | H34: Verify | J34: The free-text status written with each history entry. It is a history event, not the order's state: some entries change order_status and some do not (payment, return request, refund). The engine maps each entry to a history event (Created, Accepted, Confirmed, Shipped, Payment, Delivered, Cancelled, Return request, Refund, Returned) with its history-text map (build list ENG-30 point 5); the app does not write a code. The order's state is order_status alone: Pending, Accepted, Processing, Shipped, Payed Off, Out for Delivery, Delivered, Cancelled, Rejected, Confirmed or Returned. There is no Return Requested status. | K34: Every order_status change has an entry, and every entry text maps to a history event. | L34: The order's history, and the time it was first Delivered. | M34: F30, X-13, X-23 | N34: 14 Oct 2026: Texts seen on the platform database: Order created by <name>, Order Accepted By Seller, Confirmed by buyer, Shipped by seller, Payment Completed, Delivered (<store>), Cancelled by seller, Return requested (<RET no.>), Refund of <amount> paid (<RET no.>), Returned to seller. 29 Sep 2026: Build list APP-08.
A35: F31 | B35: order_state_changed | C35: reason_code | D35: enum · changed_mind | E35: Important | F35: R4 | G35: Aravinth | H35: Closed | J35: Not required in Wave 1A: no scoring rule uses cancel reasons. Whatever exists (reason_code or the free-text reasons) is stored for investigation. | K35: Present on every Cancelled or Rejected change, null otherwise, and only values from the list. | L35: Why. Separates a product problem from a delivery problem | M35: F31 | N35: 29 Sep 2026: Build list DB-04 and APP-11 not needed.
A36: F32 | B36: order_state_changed | C36: timestamp (tracking_info entry) | D36: datetime · 2026-11-09T11:02:00Z | E36: Blocking | F36: R7 | G36: Aravinth | H36: Verify | J36: tracking_info[].timestamp, written with the status change. Exists today. | K36: Ordered correctly against the creation time, and reflects when the change happened. | L36: When the state changed, not when the record was written | M36: F32 | N36: 14 Oct 2026: Confirmed on the platform database. 29 Sep 2026: Build list APP-08.
A37: F33 | B37: payment_state_changed | C37: order_id | D37: string · 6a48cb8237a8061b26eb067d | E37: Important | F37: R4 | G37: Aravinth | H37: Deferred | J37: Deferred with E7. | K37: Resolves to an order document, and reconciles one to one with orders created in the same window. | L37: Which order | M37: F33
A38: F34 | B38: payment_state_changed | C38: new_state | D38: enum · settled | E38: Important | F38: R4 | G38: Aravinth | H38: Deferred | J38: Deferred with E7. | K38: Every terminal state appears at least once. Reconcile counts by state against the orders collection. | L38: Settled, failed or charged back | M38: F34
A39: F35 | B39: payment_state_changed | C39: state_ts | D39: datetime · 2026-11-04T09:23:40Z | E39: Important | F39: R7 | G39: Aravinth | H39: Deferred | J39: Deferred with E7. When built, use Razorpay's own event time. | K39: Ordered correctly against the creation time, and reflects when the change happened. | L39: When | M39: F35
A40: F36 | B40: commission_state_changed | C40: commission id | D40: ObjectId · commissiontransactions._id (transactionRef CMS-…) | E40: Blocking | F40: R4 | G40: Aravinth | H40: Deferred | J40: Deferred with E8. Source: commissiontransactions. commissiontransactions._id; transactionRef is the readable reference. | K40: Resolves to a commission record. | L40: Commission record identifier | M40: F36 | N40: 14 Oct 2026: Remapped to commissiontransactions (ML Reference section 8.7); influencerearnings is not used.
A41: F37 | B41: commission_state_changed | C41: beneficiaryId, beneficiaryModel | D41: ObjectId + enum · user | businessRegister | E41: Blocking | F41: R4 | G41: Aravinth | H41: Deferred | J41: Deferred with E8. Source: commissiontransactions. The promoter who earns, and which collection the id belongs to (a store can earn too). | K41: Populated on every commission record, with its model. | L41: Which promoter earned it | M41: F37 | N41: 14 Oct 2026: Remapped to commissiontransactions (ML Reference section 8.7); influencerearnings is not used.
...

Sheet 3 Data model changes
A1: Data model changes
A2: Changes to the database itself rather than to an event.
A4: ID | B4: Item | C4: Priority | D4: Owner | E4: Status | F4: Built on / due by | G4: What is needed | H4: Consequence if not done | I4: Decided in | J4: Note
A5: D1 | B5: Return capture on the order | C5: Blocking | D5: Aravinth | E5: Verify | G5: Nothing to build. A return is order_status Returned, set by the seller, with return_info.returned_at. A buyer's request is a returnrequests record (F81), open while isActive is true. There is no Return Requested status. | H5: A returned order looks like a successful one, and every commerce label counts returns as sales. | I5: D1 | J5: 14 Oct 2026: Confirmed on the platform database (order 6a9fac747498f914bd4a50c8). Build list DB-03, APP-10, ENG-30. 28 Sep 2026: Changed to the platform's return_info structure. Build list DB-03, APP-10.
A6: D2 | B6: One canonical order status | C6: Blocking | D6: Aravinth | E6: Closed | G6: order_status is authoritative. The only remaining action is X-13. | H6: No agreed definition of a successful order. | I6: D2, X-13 | J6: The remaining action is APP-09.
A7: D3 | B7: Shared checkout identifier | C7: Blocking | D7: Aravinth | E7: Verify | G7: checkout_id on every order from one checkout. Verified as F59. | H7: Items bought together cannot be identified, so the co-purchase method cannot be built. | I7: D3, F59 | J7: Basket-of-three check still to run.
A8: D4 | B8: Campaign entity | C8: Blocking | D8: Aravinth | E8: Deferred | G8: Deferred with Engine C. | H8: Campaigns cannot be measured or attributed. | I8: D4 | J8: 14 Oct 2026: A collaboration (one store, one creator) is not a campaign. D4 stays Deferred.
A9: D5 | B9: Promoter and influencer as account states | C9: Important | D9: Aravinth | E9: Closed | G9: Not needed. Promoter stays a continuum: the engine keeps the score and its history. The platform now keeps a verified-influencer badge (users.influencerVerification: verified or revoked, with dates); no Wave 1A model reads it (X-22). | H9: — | I9: D5 | J9: Not needed: the promoter score is a continuum.
A10: D6 | B10: Timestamped social interactions | C10: Important | D10: Aravinth | E10: Closed | G10: Closed by E9: each interaction is its own timestamped event. Counters on posts stay as they are. | H10: — | I10: D6, E9
A11: D7 | B11: Stable identifiers | C11: Important | D11: Aravinth | E11: Closed | G11: MongoDB ids are never reused. | H11: User and item histories fragment silently. | I11: D7 | J11: MongoDB ids are never reused, so nothing to build.
A12: D8 | B12: Raw event retention | C12: Important | D12: Aravinth; Allen for ml_events | E12: To build | G12: Platform: 90-day expiry on short-lived postevents types and on recommendationrequests; other postevents types kept. Engine: copies kept at least 365 days from the event time, under the engine's own expiry (X-08). userevents marked deprecated in code. | H12: Training windows are truncated and seasonal patterns cannot be learned. | I12: D8, X-08 | J12: 28 Sep 2026: Replaces the platform-side 365-day raise. Build list DB-01, ENG-04.
A13: D9 | B13: Purchase privacy for incognito orders | C13: Important | D13: Aravinth; Allen for the order filter | E13: To build | G13: As X-09: everything is recorded; a buyer's identity from an incognito order is never shown to anyone else. | H13: A buyer's private purchase is shown to their followers. | I13: D9, X-09 | J13: 28 Sep 2026: Product Owner decision. Build list APP-04.
A14: D10 | B14: Change time on posts and accounts | C14: Blocking | D14: Aravinth | E14: Closed | G14: Not needed: the engine re-reads posts, accounts and products in full, and re-checks returned items when each list is built (build list ENG-27, ENG-08). | H14: A deranked, hidden or private post, or an inactive account, can keep being recommended until the next full re-read. | I14: D10 | J14: 29 Sep 2026: Build list DB-14 not needed.
A15: D11 | B15: Deleted-accounts log | C15: Important | D15: Aravinth | E15: Closed | G15: Not needed: the engine detects deleted accounts itself, with confirmation (build list ENG-28). | H15: A deleted account's data stays in the engine. | I15: D11 | J15: 29 Sep 2026: Build list DB-15 not needed.
A16: D12 | B16: Order state and history | C16: Blocking | D16: Aravinth | E16: Verify | G16: Nothing to build. order_status is the order's current state. tracking_info on the order (existing) is its history: one entry per business event, with a free-text status and a timestamp, and no actor; it includes events that do not change order_status (payment, return request, refund). The engine maps each entry to a history event and takes outcomes from order_status (build list ENG-30). Entries are added only where a code path that writes order_status writes none (build list APP-08). | H16: Order history and who cancelled cannot be read reliably. | I16: D12, E6 | J16: 14 Oct 2026: Who acted is not recorded and not needed. 29 Sep 2026: Replaces the new status log.

Sheet Rules
A1: Rules
A2: Standing rules that apply across many rows. Rows point here in the Decided in column.
A4: Ref | B4: Rule | C4: What it says | D4: Owner | E4: Note
A5: X-01 | B5: Owner of client-side events | C5: Aravinth owns E2, E3 and E13, as the contact for the Flutter app. | D5: Aravinth
A6: X-02 | B6: One event path | C6: Every event is recorded once, in the platform database: the app sends E2, E3 and E13 to SOCO_BE POST /events in batches, and SOCO_BE records its own actions and orders (postevents, orders, recommendationrequests). The engine reads them with its sync by updated_at (build list ENG-04) and never receives events directly. POST /v1/events and forwarding are retired. The older collections move into postevents in the production migration (DB-16). | D6: Aravinth (records); Allen (sync) | E6: 28 Sep 2026: Changed from forwarding to the engine sync.
A7: X-03 | B7: Every feed list emits events | C7: Every list on the feed and product surfaces produces the events, whether the engine or the fallback produced it. Fallback lists keep the platform's policy_id and their recommendationrequests row. SOCO_BE writes one rec_serve_log row per list request (F80). | D7: Aravinth | E7: 29 Sep 2026: Delivered-list record removed.
A8: X-04 | B8: Seen, and a qualified view | C8: Seen means at least 50% of the item is on screen, for every media type. A qualified view is seen and on screen for at least 3,000 ms. Video play and pause thresholds are separate. | D8: Aravinth
A9: X-05 | B9: When an impression is sent | C9: One impression per item per list, sent on leave or app background, with dwell_ms for the first spell. Not resent in the same list. Unseen items are not sent; they come from served_items and seen_ids. Post-page (post_detail) impressions are page visits, not card impressions. | D9: Aravinth
A10: X-06 | B10: Position numbering | C10: Position counts from 1, in on-screen order, within each request, with no gaps. Each page is its own request. 0 is invalid. SOCO_BE shows engine lists unchanged. | D10: Aravinth | E10: 29 Sep 2026: engine_position removed.
A11: X-07 | B11: How request_id travels | C11: request_id travels with the item: card → product detail → cart item → order. The cart item keeps the list that first added it (carts.ml); quantity changes, removal and an order without context carry that list; a re-add from another list is credited to that list. Any action not reached from a served list carries null. This is attribution only; commission rules are separate. | D11: Aravinth | E11: 28 Sep 2026: Adopted as built (answers Q4).
A12: X-08 | B12: Retention of raw events | C12: Platform: 90-day expiry on short-lived postevents types (impression, click, product_view, video_play, video_complete, search, variant_select, checkout_start) and on recommendationrequests; other types kept. Engine: copies kept at least 365 days from the event time, under its own expiry, which the platform expiry never touches. Routine expiry is not account deletion (build list DB-15, ENG-28). | D12: Aravinth; Allen for engine copies | E12: 28 Sep 2026: Replaces the platform-side 365-day raise.
A13: X-09 | B13: Incognito | C13: Incognito is purchase privacy only. Events, served lists and orders are recorded as normal (isIncognitoMode true on the order). The buyer's own recommendations and anonymous totals may use incognito orders. A buyer's identity from an incognito order is never shown to anyone else; an order with no value is treated as incognito for displays that name buyers. Fraud rules read incognito orders. | D13: Aravinth; Allen for engine outputs | E13: 28 Sep 2026: Product Owner decision. Build list APP-04.
A14: X-10 | B14: App session identifier | C14: One app session id, minted by the app's SessionService (ses_…), kept across restarts, new after 30 minutes or more away (background or closed), and not expiring during use. user_sessions is the login record and is not this identifier. | D14: Aravinth | E14: 28 Sep 2026: Reported built; device check in build list APP-01.
A15: X-11 | B15: Launch surfaces | C15: Wave 1A surfaces are feed (the home feed) and product (product detail and cart). No opportunity surface. If both cannot launch together, feed goes first. | D15: Aravinth
A16: X-12 | B16: Content feedback event | C16: E13 content_feedback is sent on not interested, hide, report or mute author. Fields F60 to F65. | D16: Aravinth
A17: X-13 | B17: One order status field | C17: E6 reads order_status only. When order_status becomes Delivered, seller_delivery_status is written in the same save. Other status fields stay for operations and are not read by the engine. | D17: Aravinth | E17: Built by APP-09. order_status has no transition guard, so the engine never assumes states arrive in order.
A18: X-14 | B18: Attribution fields on postevents | C18: Fields on postevents that are filled only on some event types: - product_id and variant_id: product events and product posts. - order_id and checkout_id: purchase rows (checkout_id also on checkout_start). - session_id: every row, the app session id (X-10). - dwell_ms: impressions (first spell), views (longest watch or time on the post page) and product_view. It replaces view_duration_seconds. - referral_code: not filled in Wave 1A. - viewer_city, viewer_gender, viewer_district, viewer_is_business: stamped on view rows by the platform for Influencer Analytics. The engine does not use them; it reads demographics from the user record. | D18: Aravinth | E18: 28 Sep 2026: Updated to the platform schema reference v4.
A19: X-15 | B19: Exploration slice | C19: is_exploration on an engine list is set by the service on 5% of feed requests and copied by the app. The platform's own is_exploration flag (about 10% of discovery posts on its lists) is a different thing and is never set on an engine list. There is no shadow mode. | D19: Allen
A20: X-16 | B20: Item adapter | C20: The engine returns items in the shape the app already uses. On the feed, a post card showing a product keeps its post id as item_id, with item_type as the app expects; product rails carry product ids. Every served item, impression and click also carries post_id and product_id as separate fields, so a post id is never read as a product id. The actor's collection comes from user_model / userModel. The sync reads platform lists with the same mapping. | D20: Aravinth; Allen | E20: 29 Sep 2026: Build list ENG-29.
A21: X-17 | B21: Engine lists shown unchanged | C21: SOCO_BE shows engine lists exactly as returned: no filtering, re-ordering, trimming or added items. The engine applies eligibility and re-checks the returned items when each list is built. SOCO_BE writes one rec_serve_log row per list request (F80). | D21: Aravinth | E21: 29 Sep 2026: Replaces dropping and the delivered-list record. Build list APP-15.
A22: X-18 | B22: Undo, own posts and order outcomes | C22: Nothing is deleted: an undo row carries undo_of and the original gets undone_at. is_self marks the author acting on their own post. Each model applies its own rule; nothing is filtered globally. An order's outcome is read from the order (order_status and tracking_info), not from the purchase row alone. A return is an order whose order_status is Returned (X-23). | D22: Allen | E22: 14 Oct 2026: Return wording changed: there is no Return Requested status. 29 Sep 2026: Order history from tracking_info.
A23: X-19 | B23: Blocks | C23: Blocks are read from followers (status blocked), in either direction, for user and business accounts, when each list is built (build list ENG-08). No blocks collection is added. Build list APP-21 test 3 checks blocking end to end. | D23: Allen | E23: Added 29 Sep 2026:
A24: X-20 | B24: Category map | C24: The platform's categories are mapped to the 23 in the engine's settings. Every category in use must be mapped; unmapped categories are reported daily and left out of category scoring until mapped (build list ENG-29). The category tree is not restructured. | D24: Allen | E24: Added 29 Sep 2026:
A25: X-21 | B25: Exemptions and test accounts | C25: Kept in the engine's settings, each entry with the account, the reason, an expiry and who changed it; every change is logged. Exempt accounts are flagged but never actioned. Test accounts are left out of learning, measurement and fraud (build list ENG-29). | D25: Allen | E25: Added 29 Sep 2026:
A26: X-22 | B26: Promoter, person and platform data | C26: orders.promoter_id is the author of the order's post (text; a user or a store), taken from the post when missing. A personal account and every store whose businessregisters.user_id is that account are one person. A repost leads back to its original through repostDetails.originalPostId. A post carrying _seedTag is test data. Not read in Wave 1A: commissiontransactions, commissionledgers, postattributions, collaborations, collaborationevents, orders.commission, orders.return_type, orders.return_summary, posts.disclosure, users.influencerVerification and the Creator Hub profiles. influencerearnings and the legacy isVerified flags are no longer maintained and are never read (build list ENG-30). | D26: Allen | E26: 14 Oct 2026: Added from the App Team ML Reference (8 Oct) and answers (13 Oct).
A27: X-23 | B27: Returns and return requests | C27: There is no Return Requested status. order_status is the order's current state; tracking_info is its history, free-text entries with a timestamp that include events which do not change the state (payment, return request, refund), and the engine maps each to a history event. A buyer's request is a returnrequests record, open while isActive is true; the order stays Delivered. The seller's return sets order_status Returned and return_info.returned_at. While a request is open, the purchase is out of M1 and the sale is out of M8's completed sales; a request that ends without a return brings both back. A missing record is never proof that no request exists. The return window is the product's deliveryConfig.returnWindow (0 when isReturnApplicable is false), counted from the first Delivered entry; a sale is past it at or after Delivered time plus window plus 2 days (build list ENG-30, ENG-16). | D27: Allen | E27: 14 Oct 2026: Added from the database checks of 13 and 14 Oct.

Sheet 4 Native event map
A1: Native event map
A2: The platform's 26 postevents types, and where each one sits in this register. Scored = used by a Wave 1A model. Capture only = copied by the engine and kept, no model weight (adding one needs its own specification).
A3: event_type | B3: E code | C3: Scored in Wave 1A | D3: Written by | E3: Note
A4: impression | B4: E2 | C4: Measurement only (M1 does not use impressions) | D4: App | E4: post_detail impressions are page visits (X-05)
A5: click | B5: E3 | C5: M1 | D5: App
A6: product_click | B6: E3 | C6: M1 | D6: Server | E6: Older builds
A7: view | B7: — | C7: M1 qualified view when dwell_ms ≥ 3,000 | D7: Server | E7: One per viewer per post
A8: like | B8: E9 | C8: M1 | D8: Server
A9: unlike | B9: E9 | C9: M1 (removes the like) | D9: Server | E9: undo_of the like
A10: comment | B10: E9 | C10: M1 | D10: Server
A11: uncomment | B11: E9 | C11: M1 (removes the comment) | D11: Server | E11: undo_of the comment
A12: share | B12: E9 | C12: M1 | D12: Server
A13: save | B13: E9 | C13: M1 | D13: Server
A14: unsave | B14: E9 | C14: M1 (removes the save) | D14: Server | E14: undo_of the save
A15: repost | B15: E9 | C15: Capture only | D15: Server
A16: follow | B16: E9 | C16: M1 (business follows) | D16: Server | E16: influencer_id = the account followed
A17: unfollow | B17: E9 | C17: M1 (removes the follow) | D17: Server | E17: undo_of the follow
A18: add_to_cart | B18: E4 | C18: M1, M5 | D18: Server | E18: list from carts.ml
A19: remove_from_cart | B19: E4 | C19: Capture only | D19: Server | E19: list from carts.ml
A20: purchase | B20: E5 | C20: M1, M5, M8 via the order | D20: Server | E20: the order is the authority (X-18)
A21: feedback | B21: E13 | C21: M1, filters | D21: App | E21: not_interested, hide, report, mute_author
A22: product_view | B22: — | C22: Capture only | D22: App
A23: video_play | B23: — | C23: Capture only | D23: App
A24: video_complete | B24: — | C24: Capture only | D24: App
A25: variant_select | B25: — | C25: Capture only | D25: App
A26: checkout_start | B26: — | C26: Capture only | D26: App | E26: carries checkout_id
A27: wishlist_add | B27: — | C27: Capture only | D27: Server
A28: wishlist_remove | B28: — | C28: Capture only | D28: Server | E28: undo_of the add
A29: search | B29: — | C29: Capture only | D29: App / server | E29: full log in searchqueries
